[2025-06-20T22:36:16.430+0000] {local_task_job_runner.py:123} INFO - ::group::Pre task execution logs
[2025-06-20T22:36:16.447+0000] {taskinstance.py:2613} INFO - Dependencies all met for dep_context=non-requeueable deps ti=<TaskInstance: dbt_dag.dbt_run manual__2025-06-20T22:31:11.255768+00:00 [queued]>
[2025-06-20T22:36:16.457+0000] {taskinstance.py:2613} INFO - Dependencies all met for dep_context=requeueable deps ti=<TaskInstance: dbt_dag.dbt_run manual__2025-06-20T22:31:11.255768+00:00 [queued]>
[2025-06-20T22:36:16.458+0000] {taskinstance.py:2866} INFO - Starting attempt 2 of 2
[2025-06-20T22:36:16.535+0000] {taskinstance.py:2889} INFO - Executing <Task(BashOperator): dbt_run> on 2025-06-20 22:31:11.255768+00:00
[2025-06-20T22:36:16.541+0000] {warnings.py:112} WARNING - /home/***/.local/lib/python3.12/site-packages/***/task/task_runner/standard_task_runner.py:70: DeprecationWarning: This process (pid=405) is multi-threaded, use of fork() may lead to deadlocks in the child.
  pid = os.fork()

[2025-06-20T22:36:16.543+0000] {standard_task_runner.py:72} INFO - Started process 406 to run task
[2025-06-20T22:36:16.544+0000] {standard_task_runner.py:104} INFO - Running: ['***', 'tasks', 'run', 'dbt_dag', 'dbt_run', 'manual__2025-06-20T22:31:11.255768+00:00', '--job-id', '10', '--raw', '--subdir', 'DAGS_FOLDER/dbt_dag.py', '--cfg-path', '/tmp/tmplx11jesl']
[2025-06-20T22:36:16.545+0000] {standard_task_runner.py:105} INFO - Job 10: Subtask dbt_run
[2025-06-20T22:36:16.606+0000] {task_command.py:467} INFO - Running <TaskInstance: dbt_dag.dbt_run manual__2025-06-20T22:31:11.255768+00:00 [running]> on host d15c782c3e87
[2025-06-20T22:36:16.685+0000] {taskinstance.py:3132} INFO - Exporting env vars: AIRFLOW_CTX_DAG_OWNER='***' AIRFLOW_CTX_DAG_ID='dbt_dag' AIRFLOW_CTX_TASK_ID='dbt_run' AIRFLOW_CTX_EXECUTION_DATE='2025-06-20T22:31:11.255768+00:00' AIRFLOW_CTX_TRY_NUMBER='2' AIRFLOW_CTX_DAG_RUN_ID='manual__2025-06-20T22:31:11.255768+00:00'
[2025-06-20T22:36:16.686+0000] {taskinstance.py:731} INFO - ::endgroup::
[2025-06-20T22:36:16.700+0000] {subprocess.py:78} INFO - Tmp dir root location: /tmp
[2025-06-20T22:36:16.702+0000] {subprocess.py:88} INFO - Running command: ['/usr/bin/bash', '-c', 'cd /opt/***/dags && dbt run --profiles-dir /opt/***/dags/.dbt']
[2025-06-20T22:36:16.714+0000] {subprocess.py:99} INFO - Output:
[2025-06-20T22:36:18.996+0000] {subprocess.py:106} INFO - [0m22:36:18  Running with dbt=1.10.2
[2025-06-20T22:36:18.998+0000] {subprocess.py:106} INFO - [0m22:36:18  Encountered an error:
[2025-06-20T22:36:18.999+0000] {subprocess.py:106} INFO - Runtime Error
[2025-06-20T22:36:18.999+0000] {subprocess.py:106} INFO -   No dbt_project.yml found at expected path /opt/***/dags/dbt_project.yml
[2025-06-20T22:36:19.000+0000] {subprocess.py:106} INFO -   Verify that each entry within packages.yml (and their transitive dependencies) contains a file named dbt_project.yml
[2025-06-20T22:36:19.001+0000] {subprocess.py:106} INFO - 
[2025-06-20T22:36:20.819+0000] {subprocess.py:110} INFO - Command exited with return code 2
[2025-06-20T22:36:20.833+0000] {taskinstance.py:3311} ERROR - Task failed with exception
Traceback (most recent call last):
  File "/home/airflow/.local/lib/python3.12/site-packages/airflow/models/taskinstance.py", line 767, in _execute_task
    result = _execute_callable(context=context, **execute_callable_kwargs)
             ^^^^^^^^^^^^^^^^^^^^^^^^^^^^^^^^^^^^^^^^^^^^^^^^^^^^^^^^^^^^^
  File "/home/airflow/.local/lib/python3.12/site-packages/airflow/models/taskinstance.py", line 733, in _execute_callable
    return ExecutionCallableRunner(
           ^^^^^^^^^^^^^^^^^^^^^^^^
  File "/home/airflow/.local/lib/python3.12/site-packages/airflow/utils/operator_helpers.py", line 252, in run
    return self.func(*args, **kwargs)
           ^^^^^^^^^^^^^^^^^^^^^^^^^^
  File "/home/airflow/.local/lib/python3.12/site-packages/airflow/models/baseoperator.py", line 417, in wrapper
    return func(self, *args, **kwargs)
           ^^^^^^^^^^^^^^^^^^^^^^^^^^^
  File "/home/airflow/.local/lib/python3.12/site-packages/airflow/operators/bash.py", line 276, in execute
    raise AirflowException(
airflow.exceptions.AirflowException: Bash command failed. The command returned a non-zero exit code 2.
[2025-06-20T22:36:20.838+0000] {taskinstance.py:1225} INFO - Marking task as FAILED. dag_id=dbt_dag, task_id=dbt_run, run_id=manual__2025-06-20T22:31:11.255768+00:00, execution_date=20250620T223111, start_date=20250620T223616, end_date=20250620T223620
[2025-06-20T22:36:20.856+0000] {taskinstance.py:340} INFO - ::group::Post task execution logs
[2025-06-20T22:36:20.857+0000] {standard_task_runner.py:124} ERROR - Failed to execute job 10 for task dbt_run (Bash command failed. The command returned a non-zero exit code 2.; 406)
Traceback (most recent call last):
  File "/home/airflow/.local/lib/python3.12/site-packages/airflow/task/task_runner/standard_task_runner.py", line 117, in _start_by_fork
    ret = args.func(args, dag=self.dag)
          ^^^^^^^^^^^^^^^^^^^^^^^^^^^^^
  File "/home/airflow/.local/lib/python3.12/site-packages/airflow/cli/cli_config.py", line 49, in command
    return func(*args, **kwargs)
           ^^^^^^^^^^^^^^^^^^^^^
  File "/home/airflow/.local/lib/python3.12/site-packages/airflow/utils/cli.py", line 116, in wrapper
    return f(*args, **kwargs)
           ^^^^^^^^^^^^^^^^^^
  File "/home/airflow/.local/lib/python3.12/site-packages/airflow/cli/commands/task_command.py", line 483, in task_run
    task_return_code = _run_task_by_selected_method(args, _dag, ti)
                       ^^^^^^^^^^^^^^^^^^^^^^^^^^^^^^^^^^^^^^^^^^^^
  File "/home/airflow/.local/lib/python3.12/site-packages/airflow/cli/commands/task_command.py", line 256, in _run_task_by_selected_method
    return _run_raw_task(args, ti)
           ^^^^^^^^^^^^^^^^^^^^^^^
  File "/home/airflow/.local/lib/python3.12/site-packages/airflow/cli/commands/task_command.py", line 341, in _run_raw_task
    return ti._run_raw_task(
           ^^^^^^^^^^^^^^^^^
  File "/home/airflow/.local/lib/python3.12/site-packages/airflow/utils/session.py", line 97, in wrapper
    return func(*args, session=session, **kwargs)
           ^^^^^^^^^^^^^^^^^^^^^^^^^^^^^^^^^^^^^^
  File "/home/airflow/.local/lib/python3.12/site-packages/airflow/models/taskinstance.py", line 3005, in _run_raw_task
    return _run_raw_task(
           ^^^^^^^^^^^^^^
  File "/home/airflow/.local/lib/python3.12/site-packages/airflow/models/taskinstance.py", line 273, in _run_raw_task
    TaskInstance._execute_task_with_callbacks(
  File "/home/airflow/.local/lib/python3.12/site-packages/airflow/models/taskinstance.py", line 3159, in _execute_task_with_callbacks
    result = self._execute_task(context, task_orig)
             ^^^^^^^^^^^^^^^^^^^^^^^^^^^^^^^^^^^^^^
  File "/home/airflow/.local/lib/python3.12/site-packages/airflow/models/taskinstance.py", line 3183, in _execute_task
    return _execute_task(self, context, task_orig)
           ^^^^^^^^^^^^^^^^^^^^^^^^^^^^^^^^^^^^^^^
  File "/home/airflow/.local/lib/python3.12/site-packages/airflow/models/taskinstance.py", line 767, in _execute_task
    result = _execute_callable(context=context, **execute_callable_kwargs)
             ^^^^^^^^^^^^^^^^^^^^^^^^^^^^^^^^^^^^^^^^^^^^^^^^^^^^^^^^^^^^^
  File "/home/airflow/.local/lib/python3.12/site-packages/airflow/models/taskinstance.py", line 733, in _execute_callable
    return ExecutionCallableRunner(
           ^^^^^^^^^^^^^^^^^^^^^^^^
  File "/home/airflow/.local/lib/python3.12/site-packages/airflow/utils/operator_helpers.py", line 252, in run
    return self.func(*args, **kwargs)
           ^^^^^^^^^^^^^^^^^^^^^^^^^^
  File "/home/airflow/.local/lib/python3.12/site-packages/airflow/models/baseoperator.py", line 417, in wrapper
    return func(self, *args, **kwargs)
           ^^^^^^^^^^^^^^^^^^^^^^^^^^^
  File "/home/airflow/.local/lib/python3.12/site-packages/airflow/operators/bash.py", line 276, in execute
    raise AirflowException(
airflow.exceptions.AirflowException: Bash command failed. The command returned a non-zero exit code 2.
[2025-06-20T22:36:20.891+0000] {local_task_job_runner.py:266} INFO - Task exited with return code 1
[2025-06-20T22:36:20.912+0000] {taskinstance.py:3895} INFO - 0 downstream tasks scheduled from follow-on schedule check
[2025-06-20T22:36:20.919+0000] {local_task_job_runner.py:245} INFO - ::endgroup::
