[2025-06-20T21:37:51.347+0000] {local_task_job_runner.py:123} INFO - ::group::Pre task execution logs
[2025-06-20T21:37:51.368+0000] {taskinstance.py:2613} INFO - Dependencies all met for dep_context=non-requeueable deps ti=<TaskInstance: dbt_dag.dbt_run scheduled__2025-06-19T00:00:00+00:00 [queued]>
[2025-06-20T21:37:51.379+0000] {taskinstance.py:2613} INFO - Dependencies all met for dep_context=requeueable deps ti=<TaskInstance: dbt_dag.dbt_run scheduled__2025-06-19T00:00:00+00:00 [queued]>
[2025-06-20T21:37:51.380+0000] {taskinstance.py:2866} INFO - Starting attempt 2 of 2
[2025-06-20T21:37:51.407+0000] {taskinstance.py:2889} INFO - Executing <Task(BashOperator): dbt_run> on 2025-06-19 00:00:00+00:00
[2025-06-20T21:37:51.420+0000] {warnings.py:112} WARNING - /home/***/.local/lib/python3.12/site-packages/***/task/task_runner/standard_task_runner.py:70: DeprecationWarning: This process (pid=233) is multi-threaded, use of fork() may lead to deadlocks in the child.
  pid = os.fork()

[2025-06-20T21:37:51.423+0000] {standard_task_runner.py:72} INFO - Started process 235 to run task
[2025-06-20T21:37:51.422+0000] {standard_task_runner.py:104} INFO - Running: ['***', 'tasks', 'run', 'dbt_dag', 'dbt_run', 'scheduled__2025-06-19T00:00:00+00:00', '--job-id', '6', '--raw', '--subdir', 'DAGS_FOLDER/dbt_dag.py', '--cfg-path', '/tmp/tmp4j_o0w3a']
[2025-06-20T21:37:51.425+0000] {standard_task_runner.py:105} INFO - Job 6: Subtask dbt_run
[2025-06-20T21:37:51.512+0000] {task_command.py:467} INFO - Running <TaskInstance: dbt_dag.dbt_run scheduled__2025-06-19T00:00:00+00:00 [running]> on host 63f149901e14
[2025-06-20T21:37:51.619+0000] {taskinstance.py:3132} INFO - Exporting env vars: AIRFLOW_CTX_DAG_OWNER='***' AIRFLOW_CTX_DAG_ID='dbt_dag' AIRFLOW_CTX_TASK_ID='dbt_run' AIRFLOW_CTX_EXECUTION_DATE='2025-06-19T00:00:00+00:00' AIRFLOW_CTX_TRY_NUMBER='2' AIRFLOW_CTX_DAG_RUN_ID='scheduled__2025-06-19T00:00:00+00:00'
[2025-06-20T21:37:51.621+0000] {logging_mixin.py:190} INFO - Task instance is in running state
[2025-06-20T21:37:51.622+0000] {logging_mixin.py:190} INFO -  Previous state of the Task instance: queued
[2025-06-20T21:37:51.622+0000] {logging_mixin.py:190} INFO - Current task name:dbt_run state:running start_date:2025-06-20 21:37:51.369449+00:00
[2025-06-20T21:37:51.623+0000] {logging_mixin.py:190} INFO - Dag name:dbt_dag and current dag run status:running
[2025-06-20T21:37:51.623+0000] {taskinstance.py:731} INFO - ::endgroup::
[2025-06-20T21:37:51.625+0000] {subprocess.py:78} INFO - Tmp dir root location: /tmp
[2025-06-20T21:37:51.626+0000] {subprocess.py:88} INFO - Running command: ['/usr/bin/bash', '-c', 'cd /opt/***/snowflake_data_pr && dbt run']
[2025-06-20T21:37:51.643+0000] {subprocess.py:99} INFO - Output:
[2025-06-20T21:37:51.645+0000] {subprocess.py:106} INFO - /usr/bin/bash: line 1: cd: /opt/***/snowflake_data_pr: No such file or directory
[2025-06-20T21:37:51.646+0000] {subprocess.py:110} INFO - Command exited with return code 1
[2025-06-20T21:37:51.661+0000] {taskinstance.py:3311} ERROR - Task failed with exception
Traceback (most recent call last):
  File "/home/airflow/.local/lib/python3.12/site-packages/airflow/models/taskinstance.py", line 767, in _execute_task
    result = _execute_callable(context=context, **execute_callable_kwargs)
             ^^^^^^^^^^^^^^^^^^^^^^^^^^^^^^^^^^^^^^^^^^^^^^^^^^^^^^^^^^^^^
  File "/home/airflow/.local/lib/python3.12/site-packages/airflow/models/taskinstance.py", line 733, in _execute_callable
    return ExecutionCallableRunner(
           ^^^^^^^^^^^^^^^^^^^^^^^^
  File "/home/airflow/.local/lib/python3.12/site-packages/airflow/utils/operator_helpers.py", line 252, in run
    return self.func(*args, **kwargs)
           ^^^^^^^^^^^^^^^^^^^^^^^^^^
  File "/home/airflow/.local/lib/python3.12/site-packages/airflow/models/baseoperator.py", line 417, in wrapper
    return func(self, *args, **kwargs)
           ^^^^^^^^^^^^^^^^^^^^^^^^^^^
  File "/home/airflow/.local/lib/python3.12/site-packages/airflow/operators/bash.py", line 276, in execute
    raise AirflowException(
airflow.exceptions.AirflowException: Bash command failed. The command returned a non-zero exit code 1.
[2025-06-20T21:37:51.667+0000] {logging_mixin.py:190} INFO - Task instance in failure state
[2025-06-20T21:37:51.668+0000] {logging_mixin.py:190} INFO - Task start:2025-06-20 21:37:51.369449+00:00 end:2025-06-20 21:37:51.666536+00:00 duration:0.297087
[2025-06-20T21:37:51.669+0000] {logging_mixin.py:190} INFO - Task:<Task(BashOperator): dbt_run> dag:<DAG: dbt_dag> dagrun:<DagRun dbt_dag @ 2025-06-19 00:00:00+00:00: scheduled__2025-06-19T00:00:00+00:00, state:running, queued_at: 2025-06-20 21:32:42.663144+00:00. externally triggered: False>
[2025-06-20T21:37:51.670+0000] {logging_mixin.py:190} INFO - Failure caused by Bash command failed. The command returned a non-zero exit code 1.
[2025-06-20T21:37:51.671+0000] {taskinstance.py:1225} INFO - Marking task as FAILED. dag_id=dbt_dag, task_id=dbt_run, run_id=scheduled__2025-06-19T00:00:00+00:00, execution_date=20250619T000000, start_date=20250620T213751, end_date=20250620T213751
[2025-06-20T21:37:51.695+0000] {taskinstance.py:340} INFO - ::group::Post task execution logs
[2025-06-20T21:37:51.696+0000] {standard_task_runner.py:124} ERROR - Failed to execute job 6 for task dbt_run (Bash command failed. The command returned a non-zero exit code 1.; 235)
Traceback (most recent call last):
  File "/home/airflow/.local/lib/python3.12/site-packages/airflow/task/task_runner/standard_task_runner.py", line 117, in _start_by_fork
    ret = args.func(args, dag=self.dag)
          ^^^^^^^^^^^^^^^^^^^^^^^^^^^^^
  File "/home/airflow/.local/lib/python3.12/site-packages/airflow/cli/cli_config.py", line 49, in command
    return func(*args, **kwargs)
           ^^^^^^^^^^^^^^^^^^^^^
  File "/home/airflow/.local/lib/python3.12/site-packages/airflow/utils/cli.py", line 116, in wrapper
    return f(*args, **kwargs)
           ^^^^^^^^^^^^^^^^^^
  File "/home/airflow/.local/lib/python3.12/site-packages/airflow/cli/commands/task_command.py", line 483, in task_run
    task_return_code = _run_task_by_selected_method(args, _dag, ti)
                       ^^^^^^^^^^^^^^^^^^^^^^^^^^^^^^^^^^^^^^^^^^^^
  File "/home/airflow/.local/lib/python3.12/site-packages/airflow/cli/commands/task_command.py", line 256, in _run_task_by_selected_method
    return _run_raw_task(args, ti)
           ^^^^^^^^^^^^^^^^^^^^^^^
  File "/home/airflow/.local/lib/python3.12/site-packages/airflow/cli/commands/task_command.py", line 341, in _run_raw_task
    return ti._run_raw_task(
           ^^^^^^^^^^^^^^^^^
  File "/home/airflow/.local/lib/python3.12/site-packages/airflow/utils/session.py", line 97, in wrapper
    return func(*args, session=session, **kwargs)
           ^^^^^^^^^^^^^^^^^^^^^^^^^^^^^^^^^^^^^^
  File "/home/airflow/.local/lib/python3.12/site-packages/airflow/models/taskinstance.py", line 3005, in _run_raw_task
    return _run_raw_task(
           ^^^^^^^^^^^^^^
  File "/home/airflow/.local/lib/python3.12/site-packages/airflow/models/taskinstance.py", line 273, in _run_raw_task
    TaskInstance._execute_task_with_callbacks(
  File "/home/airflow/.local/lib/python3.12/site-packages/airflow/models/taskinstance.py", line 3159, in _execute_task_with_callbacks
    result = self._execute_task(context, task_orig)
             ^^^^^^^^^^^^^^^^^^^^^^^^^^^^^^^^^^^^^^
  File "/home/airflow/.local/lib/python3.12/site-packages/airflow/models/taskinstance.py", line 3183, in _execute_task
    return _execute_task(self, context, task_orig)
           ^^^^^^^^^^^^^^^^^^^^^^^^^^^^^^^^^^^^^^^
  File "/home/airflow/.local/lib/python3.12/site-packages/airflow/models/taskinstance.py", line 767, in _execute_task
    result = _execute_callable(context=context, **execute_callable_kwargs)
             ^^^^^^^^^^^^^^^^^^^^^^^^^^^^^^^^^^^^^^^^^^^^^^^^^^^^^^^^^^^^^
  File "/home/airflow/.local/lib/python3.12/site-packages/airflow/models/taskinstance.py", line 733, in _execute_callable
    return ExecutionCallableRunner(
           ^^^^^^^^^^^^^^^^^^^^^^^^
  File "/home/airflow/.local/lib/python3.12/site-packages/airflow/utils/operator_helpers.py", line 252, in run
    return self.func(*args, **kwargs)
           ^^^^^^^^^^^^^^^^^^^^^^^^^^
  File "/home/airflow/.local/lib/python3.12/site-packages/airflow/models/baseoperator.py", line 417, in wrapper
    return func(self, *args, **kwargs)
           ^^^^^^^^^^^^^^^^^^^^^^^^^^^
  File "/home/airflow/.local/lib/python3.12/site-packages/airflow/operators/bash.py", line 276, in execute
    raise AirflowException(
airflow.exceptions.AirflowException: Bash command failed. The command returned a non-zero exit code 1.
[2025-06-20T21:37:51.721+0000] {local_task_job_runner.py:266} INFO - Task exited with return code 1
[2025-06-20T21:37:52.560+0000] {taskinstance.py:3895} INFO - 0 downstream tasks scheduled from follow-on schedule check
[2025-06-20T21:37:52.579+0000] {local_task_job_runner.py:245} INFO - ::endgroup::
[2025-06-20T22:20:05.493+0000] {local_task_job_runner.py:123} INFO - ::group::Pre task execution logs
[2025-06-20T22:20:05.532+0000] {taskinstance.py:2613} INFO - Dependencies all met for dep_context=non-requeueable deps ti=<TaskInstance: dbt_dag.dbt_run scheduled__2025-06-19T00:00:00+00:00 [queued]>
[2025-06-20T22:20:05.541+0000] {taskinstance.py:2613} INFO - Dependencies all met for dep_context=requeueable deps ti=<TaskInstance: dbt_dag.dbt_run scheduled__2025-06-19T00:00:00+00:00 [queued]>
[2025-06-20T22:20:05.542+0000] {taskinstance.py:2866} INFO - Starting attempt 2 of 2
[2025-06-20T22:20:05.564+0000] {taskinstance.py:2889} INFO - Executing <Task(BashOperator): dbt_run> on 2025-06-19 00:00:00+00:00
[2025-06-20T22:20:05.570+0000] {warnings.py:112} WARNING - /home/***/.local/lib/python3.12/site-packages/***/task/task_runner/standard_task_runner.py:70: DeprecationWarning: This process (pid=189) is multi-threaded, use of fork() may lead to deadlocks in the child.
  pid = os.fork()

[2025-06-20T22:20:05.572+0000] {standard_task_runner.py:72} INFO - Started process 190 to run task
[2025-06-20T22:20:05.573+0000] {standard_task_runner.py:104} INFO - Running: ['***', 'tasks', 'run', 'dbt_dag', 'dbt_run', 'scheduled__2025-06-19T00:00:00+00:00', '--job-id', '5', '--raw', '--subdir', 'DAGS_FOLDER/dbt_dag.py', '--cfg-path', '/tmp/tmpld8swy44']
[2025-06-20T22:20:05.574+0000] {standard_task_runner.py:105} INFO - Job 5: Subtask dbt_run
[2025-06-20T22:20:05.642+0000] {task_command.py:467} INFO - Running <TaskInstance: dbt_dag.dbt_run scheduled__2025-06-19T00:00:00+00:00 [running]> on host d15c782c3e87
[2025-06-20T22:20:05.740+0000] {taskinstance.py:3132} INFO - Exporting env vars: AIRFLOW_CTX_DAG_OWNER='***' AIRFLOW_CTX_DAG_ID='dbt_dag' AIRFLOW_CTX_TASK_ID='dbt_run' AIRFLOW_CTX_EXECUTION_DATE='2025-06-19T00:00:00+00:00' AIRFLOW_CTX_TRY_NUMBER='2' AIRFLOW_CTX_DAG_RUN_ID='scheduled__2025-06-19T00:00:00+00:00'
[2025-06-20T22:20:05.741+0000] {taskinstance.py:731} INFO - ::endgroup::
[2025-06-20T22:20:05.756+0000] {subprocess.py:78} INFO - Tmp dir root location: /tmp
[2025-06-20T22:20:05.758+0000] {subprocess.py:88} INFO - Running command: ['/usr/bin/bash', '-c', 'cd /opt/*** && dbt run']
[2025-06-20T22:20:05.771+0000] {subprocess.py:99} INFO - Output:
[2025-06-20T22:20:07.962+0000] {subprocess.py:106} INFO - Usage: dbt run [OPTIONS]
[2025-06-20T22:20:07.963+0000] {subprocess.py:106} INFO - Try 'dbt run -h' for help.
[2025-06-20T22:20:07.964+0000] {subprocess.py:106} INFO - 
[2025-06-20T22:20:07.965+0000] {subprocess.py:106} INFO - Error: Invalid value for '--profiles-dir': Path '/home/***/.dbt' does not exist.
[2025-06-20T22:20:08.217+0000] {subprocess.py:110} INFO - Command exited with return code 2
[2025-06-20T22:20:08.233+0000] {taskinstance.py:3311} ERROR - Task failed with exception
Traceback (most recent call last):
  File "/home/airflow/.local/lib/python3.12/site-packages/airflow/models/taskinstance.py", line 767, in _execute_task
    result = _execute_callable(context=context, **execute_callable_kwargs)
             ^^^^^^^^^^^^^^^^^^^^^^^^^^^^^^^^^^^^^^^^^^^^^^^^^^^^^^^^^^^^^
  File "/home/airflow/.local/lib/python3.12/site-packages/airflow/models/taskinstance.py", line 733, in _execute_callable
    return ExecutionCallableRunner(
           ^^^^^^^^^^^^^^^^^^^^^^^^
  File "/home/airflow/.local/lib/python3.12/site-packages/airflow/utils/operator_helpers.py", line 252, in run
    return self.func(*args, **kwargs)
           ^^^^^^^^^^^^^^^^^^^^^^^^^^
  File "/home/airflow/.local/lib/python3.12/site-packages/airflow/models/baseoperator.py", line 417, in wrapper
    return func(self, *args, **kwargs)
           ^^^^^^^^^^^^^^^^^^^^^^^^^^^
  File "/home/airflow/.local/lib/python3.12/site-packages/airflow/operators/bash.py", line 276, in execute
    raise AirflowException(
airflow.exceptions.AirflowException: Bash command failed. The command returned a non-zero exit code 2.
[2025-06-20T22:20:08.237+0000] {taskinstance.py:1225} INFO - Marking task as FAILED. dag_id=dbt_dag, task_id=dbt_run, run_id=scheduled__2025-06-19T00:00:00+00:00, execution_date=20250619T000000, start_date=20250620T222005, end_date=20250620T222008
[2025-06-20T22:20:08.284+0000] {taskinstance.py:340} INFO - ::group::Post task execution logs
[2025-06-20T22:20:08.285+0000] {standard_task_runner.py:124} ERROR - Failed to execute job 5 for task dbt_run (Bash command failed. The command returned a non-zero exit code 2.; 190)
Traceback (most recent call last):
  File "/home/airflow/.local/lib/python3.12/site-packages/airflow/task/task_runner/standard_task_runner.py", line 117, in _start_by_fork
    ret = args.func(args, dag=self.dag)
          ^^^^^^^^^^^^^^^^^^^^^^^^^^^^^
  File "/home/airflow/.local/lib/python3.12/site-packages/airflow/cli/cli_config.py", line 49, in command
    return func(*args, **kwargs)
           ^^^^^^^^^^^^^^^^^^^^^
  File "/home/airflow/.local/lib/python3.12/site-packages/airflow/utils/cli.py", line 116, in wrapper
    return f(*args, **kwargs)
           ^^^^^^^^^^^^^^^^^^
  File "/home/airflow/.local/lib/python3.12/site-packages/airflow/cli/commands/task_command.py", line 483, in task_run
    task_return_code = _run_task_by_selected_method(args, _dag, ti)
                       ^^^^^^^^^^^^^^^^^^^^^^^^^^^^^^^^^^^^^^^^^^^^
  File "/home/airflow/.local/lib/python3.12/site-packages/airflow/cli/commands/task_command.py", line 256, in _run_task_by_selected_method
    return _run_raw_task(args, ti)
           ^^^^^^^^^^^^^^^^^^^^^^^
  File "/home/airflow/.local/lib/python3.12/site-packages/airflow/cli/commands/task_command.py", line 341, in _run_raw_task
    return ti._run_raw_task(
           ^^^^^^^^^^^^^^^^^
  File "/home/airflow/.local/lib/python3.12/site-packages/airflow/utils/session.py", line 97, in wrapper
    return func(*args, session=session, **kwargs)
           ^^^^^^^^^^^^^^^^^^^^^^^^^^^^^^^^^^^^^^
  File "/home/airflow/.local/lib/python3.12/site-packages/airflow/models/taskinstance.py", line 3005, in _run_raw_task
    return _run_raw_task(
           ^^^^^^^^^^^^^^
  File "/home/airflow/.local/lib/python3.12/site-packages/airflow/models/taskinstance.py", line 273, in _run_raw_task
    TaskInstance._execute_task_with_callbacks(
  File "/home/airflow/.local/lib/python3.12/site-packages/airflow/models/taskinstance.py", line 3159, in _execute_task_with_callbacks
    result = self._execute_task(context, task_orig)
             ^^^^^^^^^^^^^^^^^^^^^^^^^^^^^^^^^^^^^^
  File "/home/airflow/.local/lib/python3.12/site-packages/airflow/models/taskinstance.py", line 3183, in _execute_task
    return _execute_task(self, context, task_orig)
           ^^^^^^^^^^^^^^^^^^^^^^^^^^^^^^^^^^^^^^^
  File "/home/airflow/.local/lib/python3.12/site-packages/airflow/models/taskinstance.py", line 767, in _execute_task
    result = _execute_callable(context=context, **execute_callable_kwargs)
             ^^^^^^^^^^^^^^^^^^^^^^^^^^^^^^^^^^^^^^^^^^^^^^^^^^^^^^^^^^^^^
  File "/home/airflow/.local/lib/python3.12/site-packages/airflow/models/taskinstance.py", line 733, in _execute_callable
    return ExecutionCallableRunner(
           ^^^^^^^^^^^^^^^^^^^^^^^^
  File "/home/airflow/.local/lib/python3.12/site-packages/airflow/utils/operator_helpers.py", line 252, in run
    return self.func(*args, **kwargs)
           ^^^^^^^^^^^^^^^^^^^^^^^^^^
  File "/home/airflow/.local/lib/python3.12/site-packages/airflow/models/baseoperator.py", line 417, in wrapper
    return func(self, *args, **kwargs)
           ^^^^^^^^^^^^^^^^^^^^^^^^^^^
  File "/home/airflow/.local/lib/python3.12/site-packages/airflow/operators/bash.py", line 276, in execute
    raise AirflowException(
airflow.exceptions.AirflowException: Bash command failed. The command returned a non-zero exit code 2.
[2025-06-20T22:20:08.314+0000] {local_task_job_runner.py:266} INFO - Task exited with return code 1
[2025-06-20T22:20:08.338+0000] {taskinstance.py:3895} INFO - 0 downstream tasks scheduled from follow-on schedule check
[2025-06-20T22:20:08.358+0000] {local_task_job_runner.py:245} INFO - ::endgroup::
[2025-06-20T22:36:18.823+0000] {local_task_job_runner.py:123} INFO - ::group::Pre task execution logs
[2025-06-20T22:36:18.842+0000] {taskinstance.py:2613} INFO - Dependencies all met for dep_context=non-requeueable deps ti=<TaskInstance: dbt_dag.dbt_run scheduled__2025-06-19T00:00:00+00:00 [queued]>
[2025-06-20T22:36:18.852+0000] {taskinstance.py:2613} INFO - Dependencies all met for dep_context=requeueable deps ti=<TaskInstance: dbt_dag.dbt_run scheduled__2025-06-19T00:00:00+00:00 [queued]>
[2025-06-20T22:36:18.852+0000] {taskinstance.py:2866} INFO - Starting attempt 2 of 2
[2025-06-20T22:36:18.887+0000] {taskinstance.py:2889} INFO - Executing <Task(BashOperator): dbt_run> on 2025-06-19 00:00:00+00:00
[2025-06-20T22:36:18.894+0000] {warnings.py:112} WARNING - /home/***/.local/lib/python3.12/site-packages/***/task/task_runner/standard_task_runner.py:70: DeprecationWarning: This process (pid=409) is multi-threaded, use of fork() may lead to deadlocks in the child.
  pid = os.fork()

[2025-06-20T22:36:18.896+0000] {standard_task_runner.py:72} INFO - Started process 410 to run task
[2025-06-20T22:36:18.897+0000] {standard_task_runner.py:104} INFO - Running: ['***', 'tasks', 'run', 'dbt_dag', 'dbt_run', 'scheduled__2025-06-19T00:00:00+00:00', '--job-id', '11', '--raw', '--subdir', 'DAGS_FOLDER/dbt_dag.py', '--cfg-path', '/tmp/tmpuynb0g13']
[2025-06-20T22:36:18.898+0000] {standard_task_runner.py:105} INFO - Job 11: Subtask dbt_run
[2025-06-20T22:36:18.977+0000] {task_command.py:467} INFO - Running <TaskInstance: dbt_dag.dbt_run scheduled__2025-06-19T00:00:00+00:00 [running]> on host d15c782c3e87
[2025-06-20T22:36:19.064+0000] {taskinstance.py:3132} INFO - Exporting env vars: AIRFLOW_CTX_DAG_OWNER='***' AIRFLOW_CTX_DAG_ID='dbt_dag' AIRFLOW_CTX_TASK_ID='dbt_run' AIRFLOW_CTX_EXECUTION_DATE='2025-06-19T00:00:00+00:00' AIRFLOW_CTX_TRY_NUMBER='2' AIRFLOW_CTX_DAG_RUN_ID='scheduled__2025-06-19T00:00:00+00:00'
[2025-06-20T22:36:19.065+0000] {taskinstance.py:731} INFO - ::endgroup::
[2025-06-20T22:36:19.079+0000] {subprocess.py:78} INFO - Tmp dir root location: /tmp
[2025-06-20T22:36:19.080+0000] {subprocess.py:88} INFO - Running command: ['/usr/bin/bash', '-c', 'cd /opt/***/dags && dbt run --profiles-dir /opt/***/dags/.dbt']
[2025-06-20T22:36:19.094+0000] {subprocess.py:99} INFO - Output:
[2025-06-20T22:36:21.385+0000] {subprocess.py:106} INFO - [0m22:36:21  Running with dbt=1.10.2
[2025-06-20T22:36:21.387+0000] {subprocess.py:106} INFO - [0m22:36:21  Encountered an error:
[2025-06-20T22:36:21.388+0000] {subprocess.py:106} INFO - Runtime Error
[2025-06-20T22:36:21.389+0000] {subprocess.py:106} INFO -   No dbt_project.yml found at expected path /opt/***/dags/dbt_project.yml
[2025-06-20T22:36:21.389+0000] {subprocess.py:106} INFO -   Verify that each entry within packages.yml (and their transitive dependencies) contains a file named dbt_project.yml
[2025-06-20T22:36:21.390+0000] {subprocess.py:106} INFO - 
[2025-06-20T22:36:23.291+0000] {subprocess.py:110} INFO - Command exited with return code 2
[2025-06-20T22:36:23.303+0000] {taskinstance.py:3311} ERROR - Task failed with exception
Traceback (most recent call last):
  File "/home/airflow/.local/lib/python3.12/site-packages/airflow/models/taskinstance.py", line 767, in _execute_task
    result = _execute_callable(context=context, **execute_callable_kwargs)
             ^^^^^^^^^^^^^^^^^^^^^^^^^^^^^^^^^^^^^^^^^^^^^^^^^^^^^^^^^^^^^
  File "/home/airflow/.local/lib/python3.12/site-packages/airflow/models/taskinstance.py", line 733, in _execute_callable
    return ExecutionCallableRunner(
           ^^^^^^^^^^^^^^^^^^^^^^^^
  File "/home/airflow/.local/lib/python3.12/site-packages/airflow/utils/operator_helpers.py", line 252, in run
    return self.func(*args, **kwargs)
           ^^^^^^^^^^^^^^^^^^^^^^^^^^
  File "/home/airflow/.local/lib/python3.12/site-packages/airflow/models/baseoperator.py", line 417, in wrapper
    return func(self, *args, **kwargs)
           ^^^^^^^^^^^^^^^^^^^^^^^^^^^
  File "/home/airflow/.local/lib/python3.12/site-packages/airflow/operators/bash.py", line 276, in execute
    raise AirflowException(
airflow.exceptions.AirflowException: Bash command failed. The command returned a non-zero exit code 2.
[2025-06-20T22:36:23.308+0000] {taskinstance.py:1225} INFO - Marking task as FAILED. dag_id=dbt_dag, task_id=dbt_run, run_id=scheduled__2025-06-19T00:00:00+00:00, execution_date=20250619T000000, start_date=20250620T223618, end_date=20250620T223623
[2025-06-20T22:36:23.341+0000] {taskinstance.py:340} INFO - ::group::Post task execution logs
[2025-06-20T22:36:23.342+0000] {standard_task_runner.py:124} ERROR - Failed to execute job 11 for task dbt_run (Bash command failed. The command returned a non-zero exit code 2.; 410)
Traceback (most recent call last):
  File "/home/airflow/.local/lib/python3.12/site-packages/airflow/task/task_runner/standard_task_runner.py", line 117, in _start_by_fork
    ret = args.func(args, dag=self.dag)
          ^^^^^^^^^^^^^^^^^^^^^^^^^^^^^
  File "/home/airflow/.local/lib/python3.12/site-packages/airflow/cli/cli_config.py", line 49, in command
    return func(*args, **kwargs)
           ^^^^^^^^^^^^^^^^^^^^^
  File "/home/airflow/.local/lib/python3.12/site-packages/airflow/utils/cli.py", line 116, in wrapper
    return f(*args, **kwargs)
           ^^^^^^^^^^^^^^^^^^
  File "/home/airflow/.local/lib/python3.12/site-packages/airflow/cli/commands/task_command.py", line 483, in task_run
    task_return_code = _run_task_by_selected_method(args, _dag, ti)
                       ^^^^^^^^^^^^^^^^^^^^^^^^^^^^^^^^^^^^^^^^^^^^
  File "/home/airflow/.local/lib/python3.12/site-packages/airflow/cli/commands/task_command.py", line 256, in _run_task_by_selected_method
    return _run_raw_task(args, ti)
           ^^^^^^^^^^^^^^^^^^^^^^^
  File "/home/airflow/.local/lib/python3.12/site-packages/airflow/cli/commands/task_command.py", line 341, in _run_raw_task
    return ti._run_raw_task(
           ^^^^^^^^^^^^^^^^^
  File "/home/airflow/.local/lib/python3.12/site-packages/airflow/utils/session.py", line 97, in wrapper
    return func(*args, session=session, **kwargs)
           ^^^^^^^^^^^^^^^^^^^^^^^^^^^^^^^^^^^^^^
  File "/home/airflow/.local/lib/python3.12/site-packages/airflow/models/taskinstance.py", line 3005, in _run_raw_task
    return _run_raw_task(
           ^^^^^^^^^^^^^^
  File "/home/airflow/.local/lib/python3.12/site-packages/airflow/models/taskinstance.py", line 273, in _run_raw_task
    TaskInstance._execute_task_with_callbacks(
  File "/home/airflow/.local/lib/python3.12/site-packages/airflow/models/taskinstance.py", line 3159, in _execute_task_with_callbacks
    result = self._execute_task(context, task_orig)
             ^^^^^^^^^^^^^^^^^^^^^^^^^^^^^^^^^^^^^^
  File "/home/airflow/.local/lib/python3.12/site-packages/airflow/models/taskinstance.py", line 3183, in _execute_task
    return _execute_task(self, context, task_orig)
           ^^^^^^^^^^^^^^^^^^^^^^^^^^^^^^^^^^^^^^^
  File "/home/airflow/.local/lib/python3.12/site-packages/airflow/models/taskinstance.py", line 767, in _execute_task
    result = _execute_callable(context=context, **execute_callable_kwargs)
             ^^^^^^^^^^^^^^^^^^^^^^^^^^^^^^^^^^^^^^^^^^^^^^^^^^^^^^^^^^^^^
  File "/home/airflow/.local/lib/python3.12/site-packages/airflow/models/taskinstance.py", line 733, in _execute_callable
    return ExecutionCallableRunner(
           ^^^^^^^^^^^^^^^^^^^^^^^^
  File "/home/airflow/.local/lib/python3.12/site-packages/airflow/utils/operator_helpers.py", line 252, in run
    return self.func(*args, **kwargs)
           ^^^^^^^^^^^^^^^^^^^^^^^^^^
  File "/home/airflow/.local/lib/python3.12/site-packages/airflow/models/baseoperator.py", line 417, in wrapper
    return func(self, *args, **kwargs)
           ^^^^^^^^^^^^^^^^^^^^^^^^^^^
  File "/home/airflow/.local/lib/python3.12/site-packages/airflow/operators/bash.py", line 276, in execute
    raise AirflowException(
airflow.exceptions.AirflowException: Bash command failed. The command returned a non-zero exit code 2.
[2025-06-20T22:36:23.366+0000] {local_task_job_runner.py:266} INFO - Task exited with return code 1
[2025-06-20T22:36:23.388+0000] {taskinstance.py:3895} INFO - 0 downstream tasks scheduled from follow-on schedule check
[2025-06-20T22:36:23.405+0000] {local_task_job_runner.py:245} INFO - ::endgroup::
